<mujoco model="go2">
  <compiler angle="radian" meshdir="assets" autolimits="false"/>

  <option timestep="0.005" impratio="5"/>
  <option cone="pyramidal" impratio="100" iterations="1" ls_iterations="5">
    <flag eulerdamp="disable"/>
  </option>

  <contact>
    <!-- Exclude collisions between all body parts -->

    <!-- Exclude trunk with thigh, hip and foot -->
    <exclude body1="FR_hip" body2="trunk"/>
    <exclude body1="FL_hip" body2="trunk"/>
    <exclude body1="RR_hip" body2="trunk"/>
    <exclude body1="RL_hip" body2="trunk"/>

    <exclude body1="FR_thigh" body2="trunk"/>
    <exclude body1="FL_thigh" body2="trunk"/>
    <exclude body1="RR_thigh" body2="trunk"/>
    <exclude body1="RL_thigh" body2="trunk"/>

    <exclude body1="FR_calf" body2="trunk"/>
    <exclude body1="FL_calf" body2="trunk"/>
    <exclude body1="RR_calf" body2="trunk"/>
    <exclude body1="RL_calf" body2="trunk"/>

    <exclude body1="FR_foot" body2="trunk"/>
    <exclude body1="FL_foot" body2="trunk"/>
    <exclude body1="RR_foot" body2="trunk"/>
    <exclude body1="RL_foot" body2="trunk"/>

    <!-- Exclude collisions between hips and thights -->
    <exclude body1="FR_hip" body2="FR_thigh"/>
    <exclude body1="FR_hip" body2="FL_thigh"/>
    <exclude body1="FR_hip" body2="RR_thigh"/>
    <exclude body1="FR_hip" body2="RL_thigh"/>

    <exclude body1="FL_hip" body2="FR_thigh"/>
    <exclude body1="FL_hip" body2="FL_thigh"/>
    <exclude body1="FL_hip" body2="RR_thigh"/>
    <exclude body1="FL_hip" body2="RL_thigh"/>

    <exclude body1="RR_hip" body2="FR_thigh"/>
    <exclude body1="RR_hip" body2="FL_thigh"/>
    <exclude body1="RR_hip" body2="RR_thigh"/>
    <exclude body1="RR_hip" body2="RL_thigh"/>

    <exclude body1="RL_hip" body2="FR_thigh"/>
    <exclude body1="RL_hip" body2="FL_thigh"/>
    <exclude body1="RL_hip" body2="RR_thigh"/>
    <exclude body1="RL_hip" body2="RL_thigh"/>

    <!-- Exclude collisions between hips and calfs -->
    <exclude body1="FR_hip" body2="FR_calf"/>
    <exclude body1="FR_hip" body2="FL_calf"/>
    <exclude body1="FR_hip" body2="RR_calf"/>
    <exclude body1="FR_hip" body2="RL_calf"/>

    <exclude body1="FL_hip" body2="FR_calf"/>
    <exclude body1="FL_hip" body2="FL_calf"/>
    <exclude body1="FL_hip" body2="RR_calf"/>
    <exclude body1="FL_hip" body2="RL_calf"/>

    <exclude body1="RR_hip" body2="FR_calf"/>
    <exclude body1="RR_hip" body2="FL_calf"/>
    <exclude body1="RR_hip" body2="RR_calf"/>
    <exclude body1="RR_hip" body2="RL_calf"/>

    <exclude body1="RL_hip" body2="FR_calf"/>
    <exclude body1="RL_hip" body2="FL_calf"/>
    <exclude body1="RL_hip" body2="RR_calf"/>
    <exclude body1="RL_hip" body2="RL_calf"/>

    <!-- Exclude collisions between hips and feet -->
    <exclude body1="FR_hip" body2="FR_foot"/>
    <exclude body1="FR_hip" body2="FL_foot"/>
    <exclude body1="FR_hip" body2="RR_foot"/>
    <exclude body1="FR_hip" body2="RL_foot"/>

    <exclude body1="FL_hip" body2="FR_foot"/>
    <exclude body1="FL_hip" body2="FL_foot"/>
    <exclude body1="FL_hip" body2="RR_foot"/>
    <exclude body1="FL_hip" body2="RL_foot"/>

    <exclude body1="RR_hip" body2="FR_foot"/>
    <exclude body1="RR_hip" body2="FL_foot"/>
    <exclude body1="RR_hip" body2="RR_foot"/>
    <exclude body1="RR_hip" body2="RL_foot"/>

    <exclude body1="RL_hip" body2="FR_foot"/>
    <exclude body1="RL_hip" body2="FL_foot"/>
    <exclude body1="RL_hip" body2="RR_foot"/>
    <exclude body1="RL_hip" body2="RL_foot"/>

    <!-- Exclude collisions between thighs and feet -->
    <exclude body1="FR_thigh" body2="FR_foot"/>
    <exclude body1="FR_thigh" body2="FL_foot"/>
    <exclude body1="FR_thigh" body2="RR_foot"/>
    <exclude body1="FR_thigh" body2="RL_foot"/>

    <exclude body1="FL_thigh" body2="FR_foot"/>
    <exclude body1="FL_thigh" body2="FL_foot"/>
    <exclude body1="FL_thigh" body2="RR_foot"/>
    <exclude body1="FL_thigh" body2="RL_foot"/>

    <exclude body1="RR_thigh" body2="FR_foot"/>
    <exclude body1="RR_thigh" body2="FL_foot"/>
    <exclude body1="RR_thigh" body2="RR_foot"/>
    <exclude body1="RR_thigh" body2="RL_foot"/>

    <exclude body1="RL_thigh" body2="FR_foot"/>
    <exclude body1="RL_thigh" body2="FL_foot"/>
    <exclude body1="RL_thigh" body2="RR_foot"/>
    <exclude body1="RL_thigh" body2="RL_foot"/>

    <!-- Exclude collisions between calfs and thighs -->
    <exclude body1="FR_calf" body2="FR_thigh"/>
    <exclude body1="FR_calf" body2="FL_thigh"/>
    <exclude body1="FR_calf" body2="RR_thigh"/>
    <exclude body1="FR_calf" body2="RL_thigh"/>

    <exclude body1="FL_calf" body2="FR_thigh"/>
    <exclude body1="FL_calf" body2="FL_thigh"/>
    <exclude body1="FL_calf" body2="RR_thigh"/>
    <exclude body1="FL_calf" body2="RL_thigh"/>

    <exclude body1="RR_calf" body2="FR_thigh"/>
    <exclude body1="RR_calf" body2="FL_thigh"/>
    <exclude body1="RR_calf" body2="RR_thigh"/>
    <exclude body1="RR_calf" body2="RL_thigh"/>

    <exclude body1="RL_calf" body2="FR_thigh"/>
    <exclude body1="RL_calf" body2="FL_thigh"/>
    <exclude body1="RL_calf" body2="RR_thigh"/>
    <exclude body1="RL_calf" body2="RL_thigh"/>

    <!-- Exclude collisions between calfs and feet -->
    <exclude body1="FR_calf" body2="FR_foot"/>
    <exclude body1="FR_calf" body2="FL_foot"/>
    <exclude body1="FR_calf" body2="RR_foot"/>
    <exclude body1="FR_calf" body2="RL_foot"/>

    <exclude body1="FL_calf" body2="FR_foot"/>
    <exclude body1="FL_calf" body2="FL_foot"/>
    <exclude body1="FL_calf" body2="RR_foot"/>
    <exclude body1="FL_calf" body2="RL_foot"/>

    <exclude body1="RR_calf" body2="FR_foot"/>
    <exclude body1="RR_calf" body2="FL_foot"/>
    <exclude body1="RR_calf" body2="RR_foot"/>
    <exclude body1="RR_calf" body2="RL_foot"/>

    <exclude body1="RL_calf" body2="FR_foot"/>
    <exclude body1="RL_calf" body2="FL_foot"/>
    <exclude body1="RL_calf" body2="RR_foot"/>
    <exclude body1="RL_calf" body2="RL_foot"/>
    
    <!-- Exclude hips, thigh, calfs and feet between each other -->
    <exclude body1="FR_hip" body2="FL_hip"/>
    <exclude body1="FR_hip" body2="RR_hip"/>
    <exclude body1="FR_hip" body2="RL_hip"/>
    <exclude body1="FL_hip" body2="RR_hip"/>
    <exclude body1="FL_hip" body2="RL_hip"/>
    <exclude body1="RR_hip" body2="RL_hip"/>

    <exclude body1="FR_thigh" body2="FL_thigh"/>
    <exclude body1="FR_thigh" body2="RR_thigh"/>
    <exclude body1="FR_thigh" body2="RL_thigh"/>
    <exclude body1="FL_thigh" body2="RR_thigh"/>
    <exclude body1="FL_thigh" body2="RL_thigh"/> 
    <exclude body1="RR_thigh" body2="RL_thigh"/>

    <exclude body1="FR_calf" body2="FL_calf"/>
    <exclude body1="FR_calf" body2="RR_calf"/>
    <exclude body1="FR_calf" body2="RL_calf"/>
    <exclude body1="FL_calf" body2="RR_calf"/>
    <exclude body1="FL_calf" body2="RL_calf"/> 
    <exclude body1="RR_calf" body2="RL_calf"/>

    <exclude body1="FR_foot" body2="FL_foot"/>
    <exclude body1="FR_foot" body2="RR_foot"/>
    <exclude body1="FR_foot" body2="RL_foot"/>
    <exclude body1="FL_foot" body2="RR_foot"/>
    <exclude body1="FL_foot" body2="RL_foot"/>
    <exclude body1="RR_foot" body2="RL_foot"/>
  </contact>

  <default>
    <default class="go2">
      <geom friction="0.6" condim="3"/>
      <joint axis="0 1 0" armature="0.01"/>
<!--      <motor ctrlrange="-23.7 23.7"/>-->
      <default class="abduction">
<!--        <joint axis="1 0 0" range="-1.0472 1.0472"/>-->
        <joint axis="1 0 0" />
      </default>
      <default class="hip">
        <default class="front_hip">
<!--          <joint range="-1.5708 3.4907"/>-->
        </default>
        <default class="back_hip">
<!--          <joint range="-0.5236 4.5379"/>-->
        </default>
      </default>
      <default class="knee">
<!--        <joint range="-2.7227 -0.83776"/>-->
<!--        <motor ctrlrange="-45.43 45.43"/>-->
      </default>
      <default class="visual">
        <geom type="mesh" contype="0" conaffinity="0" group="2"/>
      </default>
      <default class="collision">
        <geom group="3"/>
        <default class="foot">
          <geom size="0.0175" priority="1" solimp="0.015 1 0.031" condim="3"
            friction="0.8 0.02 0.01"/>
        </default>
      </default>
    </default>
  </default>

  <asset>
    <material name="metal" rgba=".9 .95 .95 1"/>
    <material name="black" rgba="0 0 0 1"/>
    <material name="white" rgba="1 1 1 1"/>
    <material name="gray" rgba="0.671705 0.692426 0.774270 1"/>

    <mesh name="base_0" file="base_0.obj"/>
    <mesh name="base_1" file="base_1.obj"/>
    <mesh name="base_2" file="base_2.obj"/>
    <mesh name="base_3" file="base_3.obj"/>
    <mesh name="base_4" file="base_4.obj"/>
    <mesh name="hip_0" file="hip_0.obj"/>
    <mesh name="hip_1" file="hip_1.obj"/>
    <mesh name="thigh_0" file="thigh_0.obj"/>
    <mesh name="thigh_1" file="thigh_1.obj"/>
    <mesh name="thigh_mirror_0" file="thigh_mirror_0.obj"/>
    <mesh name="thigh_mirror_1" file="thigh_mirror_1.obj"/>
    <mesh name="calf_0" file="calf_0.obj"/>
    <mesh name="calf_1" file="calf_1.obj"/>
    <mesh name="calf_mirror_0" file="calf_mirror_0.obj"/>
    <mesh name="calf_mirror_1" file="calf_mirror_1.obj"/>
    <mesh file="foot.obj"/>
  </asset>

  <worldbody>
    <light name="spotlight" mode="targetbodycom" target="trunk" pos="0 -1 2"/>
    <body name="trunk" pos="0 0 0.445" childclass="go2">
<!-- 
      <site name="rf_1_1" pos="0.3 0.3 -0.1" zaxis="0 0 -1"/>
      <site name="rf_1_2" pos="0.3 0.15 -0.1" zaxis="0 0 -1"/>
      <site name="rf_1_3" pos="0.3 0.0 -0.1" zaxis="0 0 -1"/>
      <site name="rf_1_4" pos="0.3 -0.15 -0.1" zaxis="0 0 -1"/>
      <site name="rf_1_5" pos="0.3 -0.3 -0.1" zaxis="0 0 -1"/>

      <site name="rf_2_1" pos="0.15 0.3 -0.1" zaxis="0 0 -1"/>
      <site name="rf_2_2" pos="0.15 0.15 -0.1" zaxis="0 0 -1"/>
      <site name="rf_2_3" pos="0.15 0.0 -0.1" zaxis="0 0 -1"/>
      <site name="rf_2_4" pos="0.15 -0.15 -0.1" zaxis="0 0 -1"/>
      <site name="rf_2_5" pos="0.15 -0.3 -0.1" zaxis="0 0 -1"/>

      <site name="rf_3_1" pos="0. 0.3 -0.1" zaxis="0 0 -1"/>
      <site name="rf_3_2" pos="0. 0.15 -0.1" zaxis="0 0 -1"/>
      <site name="rf_3_3" pos="0. 0.0 -0.1" zaxis="0 0 -1"/>
      <site name="rf_3_4" pos="0. -0.15 -0.1" zaxis="0 0 -1"/>
      <site name="rf_3_5" pos="0. -0.3 -0.1" zaxis="0 0 -1"/>

      <site name="rf_4_1" pos="-0.15 0.3 -0.1" zaxis="0 0 -1"/>
      <site name="rf_4_2" pos="-0.15 0.15 -0.1" zaxis="0 0 -1"/>
      <site name="rf_4_3" pos="-0.15 0.0 -0.1" zaxis="0 0 -1"/>
      <site name="rf_4_4" pos="-0.15 -0.15 -0.1" zaxis="0 0 -1"/>
      <site name="rf_4_5" pos="-0.15 -0.3 -0.1" zaxis="0 0 -1"/>

      <site name="rf_5_1" pos="-0.3 0.3 -0.1" zaxis="0 0 -1"/>
      <site name="rf_5_2" pos="-0.3 0.15 -0.1" zaxis="0 0 -1"/>
      <site name="rf_5_3" pos="-0.3 0.0 -0.1" zaxis="0 0 -1"/>
      <site name="rf_5_4" pos="-0.3 -0.15 -0.1" zaxis="0 0 -1"/>
      <site name="rf_5_5" pos="-0.3 -0.3 -0.1" zaxis="0 0 -1"/> -->


      <camera name="tracking" mode="trackcom" pos="0 -1 0.8" xyaxes="1 0 0 0 1 1"/>
      <inertial pos="0.021112 0 -0.005366" quat="-0.000543471 0.713435 -0.00173769 0.700719" mass="6.921"
        diaginertia="0.107027 0.0980771 0.0244531"/>
      <freejoint/>
      <geom name="base_mirror_0" mesh="base_0" material="black" class="visual"/>
      <geom name="base_mirror_1" mesh="base_1" material="black" class="visual"/>
      <geom name="base_mirror_2" mesh="base_2" material="black" class="visual"/>
      <geom name="base_mirror_3" mesh="base_3" material="white" class="visual"/>
      <geom name="base_mirror_4" mesh="base_4" material="gray" class="visual"/>
      <geom name="base_0" size="0.057 0.04675 0.057" class="collision"/>
      <geom name="base_1" size="0.05 0.045" pos="0.285 0 0.01" class="collision"/>
      <geom name="base_2" size="0.047" pos="0.293 0 -0.06" class="collision"/>
      <site name="imu" pos="-0.02557 0 0.04232"/>

      <body name="FR_hip" pos="0.1934 -0.0465 0">
        <inertial pos="-0.0054 -0.00194 -0.000105" quat="0.498237 0.505462 0.499245 0.497014" mass="0.678"
          diaginertia="0.00088403 0.000596003 0.000479967"/>
        <joint name="FR_hip_joint" class="abduction"/>
        <geom name="FR_hip_0" mesh="hip_0" material="metal" class="visual" quat="4.63268e-05 1 0 0"/>
        <geom name="FR_hip_1" mesh="hip_1" material="gray" class="visual" quat="4.63268e-05 1 0 0"/>
        <geom name="FR_hip" size="0.046 0.02" pos="0 -0.08 0" quat="0.707107 0.707107 0 0" class="collision"/>
        <body name="FR_thigh" pos="0 -0.0955 0">
          <inertial pos="-0.00374 0.0223 -0.0327" quat="0.551623 -0.0200632 0.0847635 0.829533" mass="1.152"
            diaginertia="0.00594973 0.00584149 0.000878787"/>
          <joint name="FR_thigh_joint" class="front_hip"/>
           <geom name="FR_thigh_mirror_0" mesh="thigh_mirror_0" material="metal" class="visual"/>
          <geom name="FR_thigh_mirror_1" mesh="thigh_mirror_1" material="gray" class="visual"/>
          <geom name="FR_thigh" size="0.017 0.01225 0.017" pos="-0.015 0 -0.1955" quat="0.707107 0 0.707107 0" class="collision"/>
          <body name="FR_calf" pos="0 0 -0.213">
            <inertial pos="0.00629595 0.000622121 -0.141417" quat="0.703508 -0.00450087 0.00154099 0.710672"
              mass="0.241352" diaginertia="0.0014901 0.00146356 5.31397e-05"/>
            <joint name="FR_calf_joint" class="knee"/>
             <geom name="FR_calf_mirror_0" mesh="calf_mirror_0" material="gray" class="visual"/>
            <geom name="FR_calf_mirror_1" mesh="calf_mirror_1" material="black" class="visual"/>
            <geom name="FR_calf_0" size="0.013 0.06" pos="0.01 0 -0.06" quat="0.995004 0 -0.0998334 0" class="collision"/>
            <geom name="FR_calf_1" size="0.011 0.0325" pos="0.02 0 -0.148" quat="0.999688 0 0.0249974 0" class="collision"/>
            <body name="FR_foot" pos="-0.002 0 -0.213">
              <geom mesh="foot" class="visual" material="black"/>
              <geom name="FR" class="foot"/>
              <site name="FR" type="sphere" size="0.023" group="5"/>
            </body>
          </body>
        </body>
      </body>
      <body name="FL_hip" pos="0.1934 0.0465 0">
        <inertial pos="-0.0054 0.00194 -0.000105" quat="0.497014 0.499245 0.505462 0.498237" mass="0.678"
          diaginertia="0.00088403 0.000596003 0.000479967"/>
        <joint name="FL_hip_joint" class="abduction"/>
        <geom name="FL_hip_0" mesh="hip_0" material="metal" class="visual"/>
        <geom name="FL_hip_1" mesh="hip_1" material="gray" class="visual"/>
        <geom name="FL_hip" size="0.046 0.02" pos="0 0.08 0" quat="0.707107 0.707107 0 0" class="collision"/>
        <body name="FL_thigh" pos="0 0.0955 0">
          <inertial pos="-0.00374 -0.0223 -0.0327" quat="0.829533 0.0847635 -0.0200632 0.551623" mass="1.152"
            diaginertia="0.00594973 0.00584149 0.000878787"/>
          <joint name="FL_thigh_joint" class="front_hip"/>
          <geom name="FL_thigh_0" mesh="thigh_0" material="metal" class="visual"/>
          <geom name="FL_thigh_1" mesh="thigh_1" material="gray" class="visual"/>
          <geom name="FL_thigh" size="0.017 0.01225 0.017" pos="-0.015 0 -0.1955" quat="0.707107 0 0.707107 0" class="collision"/>
          <body name="FL_calf" pos="0 0 -0.213">
            <inertial pos="0.00629595 -0.000622121 -0.141417" quat="0.710672 0.00154099 -0.00450087 0.703508"
              mass="0.241352" diaginertia="0.0014901 0.00146356 5.31397e-05"/>
            <joint name="FL_calf_joint" class="knee"/>
            <geom name="FL_calf_mirror_0" mesh="calf_0" material="gray" class="visual"/>
            <geom name="FL_calf_mirror_1" mesh="calf_1" material="black" class="visual"/>
            <geom name="FL_calf_0" size="0.013 0.06" pos="0.01 0 -0.06" quat="0.995004 0 -0.0998334 0" class="collision"/>
            <geom name="FL_calf_1" size="0.011 0.0325" pos="0.02 0 -0.148" quat="0.999688 0 0.0249974 0" class="collision"/>
            <body name="FL_foot" pos="-0.002 0 -0.213">
              <geom mesh="foot" class="visual" material="black"/>
              <geom name="FL" class="foot"/>
              <site name="FL" type="sphere" size="0.023" rgba="1 0 0 1" group="5"/>
            </body>
          </body>
        </body>
      </body>

      <body name="RR_hip" pos="-0.1934 -0.0465 0">
        <inertial pos="0.0054 -0.00194 -0.000105" quat="0.499245 0.497014 0.498237 0.505462" mass="0.678"
          diaginertia="0.00088403 0.000596003 0.000479967"/>
        <joint name="RR_hip_joint" class="abduction"/>
        <geom name="RR_hip_0" mesh="hip_0" material="metal" class="visual" quat="2.14617e-09 4.63268e-05 4.63268e-05 -1"/>
        <geom name="RR_hip_1" mesh="hip_1" material="gray" class="visual" quat="2.14617e-09 4.63268e-05 4.63268e-05 -1"/>
        <geom name="RR_hip" size="0.046 0.02" pos="0 -0.08 0" quat="0.707107 0.707107 0 0" class="collision"/>
        <body name="RR_thigh" pos="0 -0.0955 0">
          <inertial pos="-0.00374 0.0223 -0.0327" quat="0.551623 -0.0200632 0.0847635 0.829533" mass="1.152"
            diaginertia="0.00594973 0.00584149 0.000878787"/>
          <joint name="RR_thigh_joint" class="back_hip"/>
          <geom name="RR_thigh_mirror_0" mesh="thigh_mirror_0" material="metal" class="visual"/>
          <geom name="RR_thigh_mirror_1" mesh="thigh_mirror_1" material="gray" class="visual"/>
           <geom name="RR_thigh" size="0.017 0.01225 0.017" pos="-0.015 0 -0.1955" quat="0.707107 0 0.707107 0" class="collision"/>
          <body name="RR_calf" pos="0 0 -0.213">
            <inertial pos="0.00629595 0.000622121 -0.141417" quat="0.703508 -0.00450087 0.00154099 0.710672"
              mass="0.241352" diaginertia="0.0014901 0.00146356 5.31397e-05"/>
            <joint name="RR_calf_joint" class="knee"/>
            <geom name="RR_calf_mirror_0" mesh="calf_mirror_0" material="gray" class="visual"/>
            <geom name="RR_calf_mirror_1" mesh="calf_mirror_1" material="black" class="visual"/>
            <geom name="RR_calf_0" size="0.013 0.06" pos="0.01 0 -0.06" quat="0.995004 0 -0.0998334 0" class="collision"/>
            <geom name="RR_calf_1" size="0.011 0.0325" pos="0.02 0 -0.148" quat="0.999688 0 0.0249974 0" class="collision"/>
            <body name="RR_foot" pos="-0.002 0 -0.213">
              <geom mesh="foot" class="visual" material="black"/>
              <geom name="RR" class="foot"/>
              <site name="RR" type="sphere" size="0.023" group="5"/>
            </body>
          </body>
        </body>
      </body>
      <body name="RL_hip" pos="-0.1934 0.0465 0">
        <inertial pos="0.0054 0.00194 -0.000105" quat="0.505462 0.498237 0.497014 0.499245" mass="0.678"
          diaginertia="0.00088403 0.000596003 0.000479967"/>
        <joint name="RL_hip_joint" class="abduction"/>
        <geom name="RL_hip_0" mesh="hip_0" material="metal" class="visual" quat="4.63268e-05 0 1 0"/>
        <geom name="RL_hip_1" mesh="hip_1" material="gray" class="visual" quat="4.63268e-05 0 1 0"/>
        <geom name="RL_hip" size="0.046 0.02" pos="0 0.08 0" quat="0.707107 0.707107 0 0" class="collision"/>
        <body name="RL_thigh" pos="0 0.0955 0">
          <inertial pos="-0.00374 -0.0223 -0.0327" quat="0.829533 0.0847635 -0.0200632 0.551623" mass="1.152"
            diaginertia="0.00594973 0.00584149 0.000878787"/>
          <joint name="RL_thigh_joint" class="back_hip"/>
          <geom name="RL_thigh_0" mesh="thigh_0" material="metal" class="visual"/>
          <geom name="RL_thigh_1" mesh="thigh_1" material="gray" class="visual"/>
          <geom name="RL_thigh" size="0.017 0.01225 0.017" pos="-0.015 0 -0.1955" quat="0.707107 0 0.707107 0" class="collision"/>
          <body name="RL_calf" pos="0 0 -0.213">
            <inertial pos="0.00629595 -0.000622121 -0.141417" quat="0.710672 0.00154099 -0.00450087 0.703508"
              mass="0.241352" diaginertia="0.0014901 0.00146356 5.31397e-05"/>
            <joint name="RL_calf_joint" class="knee"/>
            <geom name="RL_calf_mirror_0" mesh="calf_0" material="gray" class="visual"/>
            <geom name="RL_calf_mirror_1" mesh="calf_1" material="black" class="visual"/>
            <geom name="RL_calf_0" size="0.013 0.06" pos="0.01 0 -0.06" quat="0.995004 0 -0.0998334 0" class="collision"/>
            <geom name="RL_calf_1" size="0.011 0.0325" pos="0.02 0 -0.148" quat="0.999688 0 0.0249974 0" class="collision"/>
            <body name="RL_foot" pos="-0.002 0 -0.213">
              <geom mesh="foot" class="visual" material="black"/>
              <geom name="RL" class="foot"/>
              <site name="RL" type="sphere" size="0.023" group="5"/>
            </body>
          </body>
        </body>
      </body>
    </body>
  </worldbody>

  <actuator>
    <motor class="abduction" name="FR_hip" joint="FR_hip_joint"/>
    <motor class="hip" name="FR_thigh" joint="FR_thigh_joint"/>
    <motor class="knee" name="FR_calf" joint="FR_calf_joint"/>
    <motor class="abduction" name="FL_hip" joint="FL_hip_joint"/>
    <motor class="hip" name="FL_thigh" joint="FL_thigh_joint"/>
    <motor class="knee" name="FL_calf" joint="FL_calf_joint"/>
    <motor class="abduction" name="RR_hip" joint="RR_hip_joint"/>
    <motor class="hip" name="RR_thigh" joint="RR_thigh_joint"/>
    <motor class="knee" name="RR_calf" joint="RR_calf_joint"/>
    <motor class="abduction" name="RL_hip" joint="RL_hip_joint"/>
    <motor class="hip" name="RL_thigh" joint="RL_thigh_joint"/>
    <motor class="knee" name="RL_calf" joint="RL_calf_joint"/>
  </actuator>

  <!-- <sensor>
	  <rangefinder name="rangefinder1_1" site="rf_1_1"/>
    <rangefinder name="rangefinder1_2" site="rf_1_2"/>
    <rangefinder name="rangefinder1_3" site="rf_1_3"/>
    <rangefinder name="rangefinder1_4" site="rf_1_4"/>
    <rangefinder name="rangefinder1_5" site="rf_1_5"/>

    <rangefinder name="rangefinder2_1" site="rf_2_1"/>
    <rangefinder name="rangefinder2_2" site="rf_2_2"/>
    <rangefinder name="rangefinder2_3" site="rf_2_3"/>
    <rangefinder name="rangefinder2_4" site="rf_2_4"/>
    <rangefinder name="rangefinder2_5" site="rf_2_5"/>

    <rangefinder name="rangefinder3_1" site="rf_3_1"/>
    <rangefinder name="rangefinder3_2" site="rf_3_2"/>
    <rangefinder name="rangefinder3_3" site="rf_3_3"/>
    <rangefinder name="rangefinder3_4" site="rf_3_4"/>
    <rangefinder name="rangefinder3_5" site="rf_3_5"/>

    <rangefinder name="rangefinder4_1" site="rf_4_1"/>
    <rangefinder name="rangefinder4_2" site="rf_4_2"/>
    <rangefinder name="rangefinder4_3" site="rf_4_3"/>
    <rangefinder name="rangefinder4_4" site="rf_4_4"/>
    <rangefinder name="rangefinder4_5" site="rf_4_5"/>

    <rangefinder name="rangefinder5_1" site="rf_5_1"/>
    <rangefinder name="rangefinder5_2" site="rf_5_2"/>
    <rangefinder name="rangefinder5_3" site="rf_5_3"/>
    <rangefinder name="rangefinder5_4" site="rf_5_4"/>
    <rangefinder name="rangefinder5_5" site="rf_5_5"/>

  </sensor> -->

  <keyframe>
    <key name="home" qpos="0 0 0.27 1 0 0 0 0 0.9 -1.8 0 0.9 -1.8 0 0.9 -1.8 0 0.9 -1.8"
      ctrl="0 0.9 -1.8 0 0.9 -1.8 0 0.9 -1.8 0 0.9 -1.8"/>
  </keyframe>
</mujoco>